Workbook

Sheet Raw_Data
A1: Inspection_ID | B1: Inspection_Date | C1: Plant | D1: Production_Line | E1: Product | F1: Shift | G1: Machine_ID | H1: Operator_ID | I1: Batch_ID | J1: Production_Qty | K1: Defect_Qty | L1: Defect_Type | M1: Downtime_Min | N1: Cycle_Time_Sec | O1: Temperature_C | P1: Pressure_Bar | Q1: Vibration_mm_s | R1: Material_Batch | S1: Supplier | T1: Inspection_Status
A2: 10908 | B2: 45934 | C2: Plant A | D2: Line 4 | E2: Widget A | F2: Morning | G2: M-09 | H2: OP-128 | I2: B1005 | J2: 1228 | K2: 10 | L2: Color Defect | M2: 116 | N2: 57 | O2: 58.8 | P2: 5.33 | Q2: 2.63 | R2: MB-211 | S2: Supplier Y | T2: Pass
A3: 10618 | B3: 45670 | C3: Plant C | D3: Line 3 | E3: Widget B | F3: Morning | G3: M-04 | H3: OP-149 | I3: B1194 | J3: 1296 | K3: 10 | L3: Dent | M3: 89 | N3: 35.7 | O3: 71.4 | P3: 5.12 | Q3: 4.86 | R3: MB-200 | S3: Supplier Z | T3: Pass
A4: 11387 | B4: 45851 | C4: Plant A | D4: Line 4 | E4: Widget C | F4: Evening | G4: M-02 | H4: OP-142 | I4: B1165 | J4: 1284 | K4: 49 | L4: Scratch | M4: 7 | N4: 40.7 | O4: 84.5 | P4: 6.13 | Q4: 3.13 | R4: MB-202 | S4: Supplier W | T4: Review
A5: 10942 | B5: 45837 | C5: Plant B | D5: Line 4 | E5: Widget A | F5: Morning | G5: M-07 | H5: OP-117 | I5: B1070 | J5: 874 | K5: 10 | L5: Dent | M5: 158 | N5: 13.5 | O5: 63.1 | P5: 3.78 | Q5: 4.06 | R5: MB-208 | S5: Supplier Y | T5: Pass
A6: 10304 | B6: 45857 | C6: Plant C | D6: Line 3 | E6: Widget C | F6: Evening | G6: M-12 | H6: OP-130 | I6: B1003 | J6: 1381 | K6: 37 | L6: Assembly Error | M6: 171 | N6: 41.6 | O6: 75.9 | P6: 5.43 | Q6: 0.6 | R6: MB-221 | S6: Supplier Z | T6: Pass
A7: 11480 | B7: 45856 | C7: Plant C | D7: Line 2 | E7: Widget C | F7: Evening | G7: M-10 | H7: OP-135 | I7: B1128 | J7: 1098 | K7: 5 | L7: Scratch | M7: 49 | N7: 41.3 | O7: 69.4 | P7: 4.56 | Q7: 0.73 | R7: MB-203 | S7: Supplier Z | T7: Pass
A8: 10176 | B8: 45825 | C8: Plant C | D8: Line 1 | E8: Widget A | F8: NIGHT | G8: M-04 | H8: OP-147 | I8: B1062 | J8: 1364 | K8: 13 | L8: Dimension Error | M8: 114 | N8: 35.6 | O8: 65.3 | P8: 5.15 | Q8: 2.01 | R8: MB-202 | S8: Supplier Y | T8: Pass
A9: 10343 | B9: 45673 | C9: Plant B | D9: Line 4 | E9: Widget C | F9: Evening | G9: M-02 | H9: OP-143 | I9: B1016 | J9: 1308 | K9: 16 | L9: Crack | M9: 36 | N9: 40.2 | O9: 59.2 | P9: 4.61 | Q9: 3.52 | R9: MB-227 | S9: Supplier X | T9: Pass
A10: 11309 | B10: 45916 | C10: Plant A | D10: Line 3 | E10: Widget A | F10: Evening | G10: M-06 | H10: OP-139 | I10: B1152 | J10: 916 | K10: 60 | L10: Scratch | M10: 68 | N10: 49.8 | O10: 82.4 | P10: 3.78 | Q10: 3.32 | R10: MB-235 | S10: Supplier X | T10: Review
A11: 11230 | B11: 45933 | C11: Plant C | D11: Line 1 | E11: Widget A | F11: Morning | G11: M-02 | H11: OP-123 | I11: B1104 | J11: 650 | K11: 33 | L11: Dent | M11: 97 | N11: 31.8 | O11: 73.9 | P11: 5.07 | Q11: 4.02 | R11: MB-241 | S11: Supplier Z | T11: Review
A12: 10585 | B12: 45830 | C12: Plant A | D12: Line 2 | E12: Widget C | F12: Night | G12: M-06 | H12: OP-114 | I12: B1119 | J12: 949 | K12: 11 | L12: Crack | M12: 156 | N12: 33.6 | O12: 56.1 | P12: 5.41 | Q12: 2.47 | R12: MB-237 | S12: Supplier Z | T12: Pass
A13: 10549 | B13: 45947 | C13: Plant A | D13: Line 1 | E13: Widget C | F13: Evening | G13: M-07 | H13: OP-131 | I13: B1039 | J13: 929 | K13: 37 | L13: Crack | M13: 146 | N13: 31.2 | O13: 82.6 | P13: 6.46 | Q13: 1.85 | R13: MB-244 | S13: Supplier X | T13: Review
... A22: 11115 | B22: 45907 | C22: Plant C | D22: Line 1 | E22: Widget C | F22: morning | G22: M-11 | H22: OP-119 | I22: B1125 | J22: 764 | K22: 3 | L22: Dent | M22: 85 | N22: 47.8 | O22: 57.6 | P22: 6.39 | Q22: 4.71 | R22: MB-241 | S22: Supplier W | T22: Pass
A23: 10454 | B23: 45832 | C23: Plant C | D23: Line 1 | E23: Widget A | F23: Morning | G23: M-02 | H23: OP-107 | I23: B1048 | J23: 582 | K23: 5 | L23: Assembly Error | M23: 20 | N23: 57 | P23: 3.61 | Q23: 1.15 | R23: MB-225 | S23: Supplier Y | T23: Pass
A24: 10472 | B24: 45829 | C24: Plant A | D24: Line 1 | E24: Widget D | F24: Morning | G24: M-07 | H24: OP-145 | I24: B1133 | J24: 1518 | K24: 15 | L24: Assembly Error | M24: 28 | N24: 46.8 | O24: 79.7 | P24: 4.22 | Q24: 5.22 | R24: MB-223 | S24: Supplier W | T24: Pass
A25: 10325 | B25: 45726 | C25: Plant A | D25: Line 2 | E25: Widget A | F25: Evening | G25: M-04 | H25: OP-136 | I25: B1145 | J25: 1485 | K25: 51 | L25: Scratch | M25: 13 | N25: 38.9 | O25: 64 | P25: 6.02 | Q25: 2.08 | R25: MB-214 | S25: Supplier X | T25: Review
A26: 10428 | B26: 45737 | C26: Plant B | D26: Line 1 | E26: Widget B | F26: Night | G26: M-06 | H26: OP-108 | I26: B1130 | J26: 657 | K26: 8 | L26: Color Defect | M26: 29 | N26: 35.7 | O26: 80.6 | P26: 5.6 | Q26: 2.17 | R26: MB-230 | S26: Supplier X | T26: Pass
A27: 11218 | B27: 46001 | C27: Plant B | D27: Line 2 | E27: Widget D | F27: Evening | G27: M-01 | H27: OP-109 | I27: B1153 | J27: 674 | K27: 11 | L27: Color Defect | M27: 28 | N27: 45.1 | O27: 63.6 | P27: 5.47 | Q27: 2.18 | R27: MB-247 | S27: Supplier X | T27: Pass
A28: 10462 | B28: 45909 | C28: Plant A | D28: Line 4 | E28: Widget D | F28: Morning | G28: M-03 | H28: OP-147 | I28: B1011 | J28: 768 | K28: 68 | L28: Color Defect | M28: 153 | N28: 46.3 | O28: 75.1 | P28: 4.97 | Q28: 3.63 | R28: MB-234 | S28: Supplier X | T28: Review
A29: 10307 | B29: 45795 | C29: Plant C | D29: Line 4 | E29: Widget A | F29: Morning | G29: M-03 | H29: OP-105 | I29: B1136 | J29: 958 | K29: 4 | L29: Dimension Error | M29: 25 | N29: 44.1 | O29: 71.5 | P29: 4.29 | Q29: 1.82 | R29: MB-243 | S29: Supplier X | T29: Pass
A30: 11465 | B30: 45929 | C30: Plant A | D30: Line 3 | E30: Widget A | F30: Morning | G30: M-08 | H30: OP-118 | I30: B1034 | J30: 700 | K30: 6 | L30: Color Defect | M30: 178 | N30: 26.5 | O30: 71.7 | P30: 4.33 | Q30: 2.94 | R30: MB-237 | S30: Supplier W | T30: Pass
A31: 10799 | B31: 45676 | C31: Plant B | D31: Line 3 | E31: Widget B | F31: Night | G31: M-10 | H31: OP-135 | I31: B1126 | J31: 625 | K31: 8 | L31: Color Defect | M31: 62 | N31: 51.1 | O31: 71.4 | P31: 5.37 | Q31: 2.69 | R31: MB-201 | S31: Supplier W | T31: Pass
A32: 10310 | B32: 45727 | C32: Plant A | D32: Line 3 | E32: Widget D | F32: Evening | G32: M-02 | H32: OP-150 | I32: B1152 | J32: 1589 | K32: 14 | L32: Dent | M32: 144 | N32: 44.8 | O32: 77.7 | Q32: 2.44 | R32: MB-201 | S32: Supplier W | T32: Pass
A33: 10352 | B33: 45947 | C33: Plant B | D33: Line 3 | E33: Widget B | F33: Evening | G33: M-03 | H33: OP-118 | I33: B1040 | J33: 829 | K33: 30 | L33: Assembly Error | M33: 52 | N33: 42.8 | O33: 65 | P33: 4.94 | Q33: 3.45 | R33: MB-226 | T33: Review
A34: 10827 | B34: 45794 | C34: Plant B | D34: Line 4 | E34: Widget A | F34: Night | G34: M-11 | H34: OP-115 | I34: B1195 | J34: 581 | K34: 2 | L34: Crack | M34: 74 | N34: 43.6 | O34: 70 | P34: 5.19 | Q34: 4.57 | R34: MB-212 | S34: Supplier Z | T34: Pass
A35: 10142 | B35: 45720 | C35: Plant B | D35: Line 3 | E35: Widget C | F35: Morning | G35: M-07 | H35: OP-116 | I35: B1113 | J35: 960 | K35: 35 | L35: Crack | M35: 26 | N35: 49.9 | O35: 79.6 | P35: 4.58 | Q35: 3.25 | R35: MB-220 | S35: Supplier W | T35: Review
A36: 10953 | B36: 45727 | C36: Plant B | D36: Line 4 | E36: Widget A | F36: Morning | G36: M-11 | H36: OP-109 | I36: B1076 | J36: 473 | K36: 36 | L36: Crack | M36: 18 | N36: 44 | O36: 66.2 | P36: 4.73 | Q36: 4.09 | R36: MB-233 | S36: Supplier X | T36: Review
A37: 10465 | B37: 45984 | C37: Plant B | D37: Line 2 | E37: Widget B | F37: Evening | G37: M-10 | H37: OP-129 | I37: B1072 | J37: 1069 | K37: 7 | L37: Scratch | M37: 104 | N37: 42.5 | O37: 85.6 | P37: 3.71 | Q37: 1.25 | R37: MB-232 | S37: Supplier Y | T37: Pass
A38: 10722 | B38: 45928 | C38: Plant-C | D38: Line 3 | E38: Widget B | F38: Evening | G38: M-07 | H38: OP-118 | I38: B1149 | J38: 700 | K38: 5 | L38: Assembly Error | M38: 65 | N38: 42.2 | O38: 76.6 | P38: 5.63 | Q38: 0.09 | R38: MB-207 | S38: Supplier X | T38: Pass
A39: 10721 | B39: 45724 | C39: Plant C | D39: Line 2 | E39: Widget B | F39: Night | G39: M-12 | H39: OP-110 | I39: B1048 | J39: 1408 | K39: 5 | L39: Dimension Error | M39: 19 | N39: 43.5 | P39: 7.37 | Q39: 1.09 | R39: MB-229 | S39: Supplier X | T39: Pass
A40: 11151 | B40: 45703 | C40: Plant C | D40: Line 1 | E40: Widget B | F40: Morning | G40: M-12 | H40: OP-117 | I40: B1008 | J40: 1039 | K40: 13 | L40: Color Defect | M40: 74 | N40: 38.2 | P40: 4.61 | Q40: 2.78 | R40: MB-218 | S40: Supplier X | T40: Pass
A41: 11007 | B41: 46012 | C41: plant c | D41: Line 1 | E41: Widget C | F41: Morning | G41: M-02 | H41: OP-123 | I41: B1190 | J41: 1057 | K41: 14 | L41: Scratch | M41: 51 | N41: 34.2 | O41: 71.7 | P41: 4.85 | Q41: 4.07 | R41: MB-233 | S41: Supplier Z | T41: Pass
A42: 11179 | B42: 45941 | C42: Plant B | D42: Line 4 | E42: Widget D | F42: Night | G42: M-10 | I42: B1004 | J42: 1369 | K42: 18 | L42: Assembly Error | M42: 105 | N42: 40.7 | O42: 68.4 | P42: 5.82 | Q42: 4.37 | R42: MB-236 | S42: Supplier X | T42: Pass
A43: 10599 | B43: 45938 | C43: Plant A | D43: Line 3 | E43: Widget A | F43: Morning | G43: M-06 | H43: OP-149 | I43: B1111 | J43: 648 | K43: 1 | L43: Assembly Error | M43: 90 | N43: 32.6 | O43: 67.6 | P43: 4.83 | Q43: 3.73 | R43: MB-241 | S43: Supplier Y | T43: Pass
A44: 10808 | B44: 45953 | C44: Plant A | D44: Line 3 | E44: Widget D | F44: Evening | G44: M-12 | H44: OP-141 | I44: B1028 | J44: 1023 | K44: 3 | L44: Dent | M44: 27 | N44: 37.3 | O44: 71.3 | P44: 4.53 | Q44: 2.9 | R44: MB-236 | S44: Supplier Y | T44: Pass
A45: 10068 | B45: 45883 | C45: Plant A | D45: Line 4 | E45: Widget A | F45: morning | G45: M-09 | H45: OP-139 | I45: B1014 | J45: 1506 | K45: 9 | L45: Dent | M45: 123 | N45: 38.2 | O45: 79 | P45: 5.57 | Q45: 3.44 | R45: MB-219 | S45: Supplier Y | T45: Pass
A46: 10900 | B46: 45761 | C46: Plant B | D46: Line 1 | E46: Widget C | F46: Evening | G46: M-06 | H46: OP-138 | I46: B1130 | J46: 1578 | K46: 19 | L46: Dent | M46: 116 | N46: 41.2 | O46: 80.4 | P46: 5.53 | Q46: 2.44 | R46: MB-223 | S46: Supplier W | T46: Pass
A47: 10298 | B47: 45870 | C47: Plant A | D47: Line 1 | E47: Widget A | F47: Evening | G47: M-09 | H47: OP-131 | I47: B1051 | J47: 1140 | K47: 10 | L47: Assembly Error | M47: 44 | N47: 39.1 | O47: 71.5 | P47: 5.52 | Q47: 3.09 | R47: MB-228 | S47: Supplier Z | T47: Pass
A48: 11280 | B48: 45727 | C48: Plant C | D48: Line 3 | E48: Widget D | F48: Evening | G48: M-05 | H48: OP-108 | I48: B1063 | J48: 894 | K48: 13 | L48: Dimension Error | M48: 162 | N48: 42.9 | O48: 70.5 | P48: 6.1 | Q48: 2.63 | R48: MB-208 | S48: Supplier Z | T48: Pass
...

Sheet Clean_Data
A1: Inspection_ID | B1: Inspection_Date | C1: Plant | D1: Production_Line | E1: Product | F1: Shift | G1: Machine_ID | H1: Operator_ID | I1: Batch_ID | J1: Production_Qty | K1: Defect_Qty | L1: Defect_Type | M1: Downtime_Min | N1: Cycle_Time_Sec | O1: Temperature_C | P1: Pressure_Bar | Q1: Vibration_mm_s | R1: Material_Batch | S1: Supplier | T1: Inspection_Status | U1: Temperature_Flag | V1: Pressure_Flag | W1: Vibration_Flag | X1: Column1
A2: 10063 | B2: 45924 | C2: Plant A | D2: Line 4 | E2: Widget C | F2: Morning | G2: M-09 | H2: OP-103 | I2: B1152 | J2: 1230 | K2: 6 | L2: Dent | M2: 80 | N2: 41.5 | O2: 160 | P2: 5.3 | Q2: 3.05 | R2: MB-233 | S2: Supplier W | T2: Pass | U2: =IF(OR(O2<20,O2>100),"Investigate","Normal") -> Investigate | V2: =IF(OR(P2<2,P2>10),"Investigate","Normal") -> Normal | W2: =IF(Q2>10,"Investigate","Normal") -> Normal
A3: 10611 | B3: 45846 | C3: Plant A | D3: Line 2 | E3: Widget B | F3: Night | G3: M-06 | H3: OP-124 | I3: B1175 | J3: 621 | K3: 19 | L3: Dent | M3: 37 | N3: 41.6 | O3: 145 | P3: 5.68 | Q3: 3.97 | R3: MB-241 | S3: Supplier Z | T3: Review | U3: =IF(OR(O3<20,O3>100),"Investigate","Normal") -> Investigate | V3: =IF(OR(P3<2,P3>10),"Investigate","Normal") -> Normal | W3: =IF(Q3>10,"Investigate","Normal") -> Normal
A4: 11147 | B4: 45675 | C4: Plant B | D4: Line 3 | E4: Widget B | F4: Evening | G4: M-10 | H4: OP-112 | I4: B1103 | J4: 1236 | K4: 43 | L4: Color Defect | M4: 159 | N4: 50.6 | O4: 95.6 | P4: 4.53 | Q4: 0.13 | R4: MB-237 | S4: Supplier Z | T4: Review | U4: =IF(OR(O4<20,O4>100),"Investigate","Normal") -> Normal | V4: =IF(OR(P4<2,P4>10),"Investigate","Normal") -> Normal | W4: =IF(Q4>10,"Investigate","Normal") -> Normal
A5: 10127 | B5: 45961 | C5: Plant A | D5: Line 3 | E5: Widget D | F5: Morning | G5: M-09 | H5: OP-109 | I5: B1067 | J5: 717 | K5: 7 | L5: Color Defect | M5: 39 | N5: 46.6 | O5: 93.5 | P5: 3.75 | Q5: 2.04 | R5: MB-211 | S5: Supplier Y | T5: Pass | U5: =IF(OR(O5<20,O5>100),"Investigate","Normal") -> Normal | V5: =IF(OR(P5<2,P5>10),"Investigate","Normal") -> Normal | W5: =IF(Q5>10,"Investigate","Normal") -> Normal
A6: 10882 | B6: 45809 | C6: Plant A | D6: Line 2 | E6: Widget C | F6: Morning | G6: M-11 | H6: OP-108 | I6: B1196 | J6: 1332 | K6: 5 | L6: Crack | M6: 77 | N6: 44.6 | O6: 92.3 | P6: 5.27 | Q6: 2.51 | R6: MB-219 | S6: Supplier W | T6: Pass | U6: =IF(OR(O6<20,O6>100),"Investigate","Normal") -> Normal | V6: =IF(OR(P6<2,P6>10),"Investigate","Normal") -> Normal | W6: =IF(Q6>10,"Investigate","Normal") -> Normal
A7: 10422 | B7: 45984 | C7: Plant C | D7: Line 2 | E7: Widget A | F7: Morning | G7: M-12 | H7: OP-118 | I7: B1095 | J7: 1441 | K7: 128 | L7: Color Defect | M7: 60 | N7: 42.6 | O7: 92.1 | P7: 5.34 | Q7: 0.03 | R7: MB-204 | S7: Supplier X | T7: Review | U7: =IF(OR(O7<20,O7>100),"Investigate","Normal") -> Normal | V7: =IF(OR(P7<2,P7>10),"Investigate","Normal") -> Normal | W7: =IF(Q7>10,"Investigate","Normal") -> Normal
A8: 10796 | B8: 45783 | C8: Plant C | D8: Line 3 | E8: Widget C | F8: Evening | G8: M-04 | H8: OP-114 | I8: B1096 | J8: 725 | K8: 7 | L8: Crack | M8: 177 | N8: 33.5 | O8: 92 | P8: 5.42 | Q8: 3.24 | R8: MB-222 | S8: Supplier Z | T8: Pass | U8: =IF(OR(O8<20,O8>100),"Investigate","Normal") -> Normal | V8: =IF(OR(P8<2,P8>10),"Investigate","Normal") -> Normal | W8: =IF(Q8>10,"Investigate","Normal") -> Normal
A9: 11500 | B9: 45921 | C9: Plant C | D9: Line 2 | E9: Widget C | F9: Evening | G9: M-04 | H9: OP-108 | I9: B1087 | J9: 1118 | K9: 12 | L9: Assembly Error | M9: 50 | N9: 35.1 | O9: 91.4 | P9: 6.29 | Q9: 3.01 | R9: MB-223 | S9: Supplier Z | T9: Pass | U9: =IF(OR(O9<20,O9>100),"Investigate","Normal") -> Normal | V9: =IF(OR(P9<2,P9>10),"Investigate","Normal") -> Normal | W9: =IF(Q9>10,"Investigate","Normal") -> Normal
A10: 11067 | B10: 45994 | C10: Plant B | D10: Line 4 | E10: Widget C | F10: Morning | G10: M-02 | H10: Unknown | I10: B1151 | J10: 865 | K10: 20 | L10: Dimension Error | M10: 22 | N10: 38.8 | O10: 91.4 | P10: 4.67 | Q10: 2.25 | R10: MB-247 | S10: Supplier X | T10: Pass | U10: =IF(OR(O10<20,O10>100),"Investigate","Normal") -> Normal | V10: =IF(OR(P10<2,P10>10),"Investigate","Normal") -> Normal | W10: =IF(Q10>10,"Investigate","Normal") -> Normal
A11: 10342 | B11: 45895 | C11: Plant A | D11: Line 3 | E11: Widget D | F11: Morning | G11: M-01 | H11: OP-132 | I11: B1188 | J11: 1237 | K11: 43 | L11: Assembly Error | M11: 21 | N11: 46.4 | O11: 91.1 | P11: 5.51 | Q11: 2.85 | R11: MB-223 | S11: Supplier X | T11: Review | U11: =IF(OR(O11<20,O11>100),"Investigate","Normal") -> Normal | V11: =IF(OR(P11<2,P11>10),"Investigate","Normal") -> Normal | W11: =IF(Q11>10,"Investigate","Normal") -> Normal
A12: 10927 | B12: 45805 | C12: Plant C | D12: Line 2 | E12: Widget A | F12: Morning | G12: M-07 | H12: OP-144 | I12: B1117 | J12: 672 | K12: 8 | L12: Dimension Error | M12: 104 | N12: 40.7 | O12: 90.8 | P12: 5.31 | Q12: 3.97 | R12: MB-246 | S12: Supplier Y | T12: Pass | U12: =IF(OR(O12<20,O12>100),"Investigate","Normal") -> Normal | V12: =IF(OR(P12<2,P12>10),"Investigate","Normal") -> Normal | W12: =IF(Q12>10,"Investigate","Normal") -> Normal
A13: 11072 | B13: 45769 | C13: Plant A | D13: Line 4 | E13: Widget D | F13: Evening | G13: M-04 | H13: OP-146 | I13: B1033 | J13: 749 | K13: 17 | L13: Dimension Error | M13: 145 | N13: 42.1 | O13: 90.8 | P13: 5.81 | Q13: 0.33 | R13: MB-250 | S13: Supplier Z | T13: Pass | U13: =IF(OR(O13<20,O13>100),"Investigate","Normal") -> Normal | V13: =IF(OR(P13<2,P13>10),"Investigate","Normal") -> Normal | W13: =IF(Q13>10,"Investigate","Normal") -> Normal
... A1501: 10605 | B1501: 45955 | C1501: Plant B | D1501: Line 2 | E1501: Widget A | F1501: Morning | G1501: M-05 | H1501: OP-110 | I1501: B1149 | J1501: 875 | K1501: 7 | L1501: Crack | M1501: 161 | N1501: 37.6 | O1501: 12 | P1501: 5.01 | Q1501: 3.02 | R1501: MB-241 | S1501: Supplier X | T1501: Pass | U1501: =IF(OR(O1501<20,O1501>100),"Investigate","Normal") -> Investigate | V1501: =IF(OR(P1501<2,P1501>10),"Investigate","Normal") -> Normal | W1501: =IF(Q1501>10,"Investigate","Normal") -> Normal

Sheet Data_Quality_Notes
A1: Issue | B1: Column(s) | C1: Action
A2: Duplicate records | B2: Inspection_ID | C2: 10 exact duplicate records removed using Excel Remove Duplicates
A3: Missing values | B3: Operator_ID | C3: 18 missing values replaced with "Unknown"
A4: Missing values | B4: Supplier | C4: 15 missing values replaced with "Unknown"
A5: Missing values | B5: Temperature_C | C5: Missing values replaced with median temperature of 71.5°C
A6: Missing values | B6: Pressure_Bar | C6: 15 missing values replaced with median pressure of 5.2 bar
A7: Missing values | B7: Defect_Type | C7: 12 missing values replaced with "Unknown" because all corresponding records had Defect_Qty > 0
A8: Inconsistent text | B8: Plant | C8: Standardized plant names to Plant A, Plant B, Plant C
A9: Inconsistent text | B9: Shift | C9: Standardized all shift names to Morning, Evening, and Night
A10: Numeric values stored as text | B10: Production_Qty | C10: Converted numeric values stored as text to numeric format
A11: Numeric values stored as text | B11: Defect_Qty | C11: Converted numeric values stored as text to numeric format
A12: Numeric values stored as text | B12: Downtime_Min | C12: Converted numeric values stored as text to numeric format
... A18: Duplicate Inspection IDs | B18: Inspection_ID | C18: Removed 2 additional duplicate IDs; 1,500 unique inspections remain

Sheet KPI_Analysis
A1: Manufacturing Quality Analytics — KPI Summary
A2: KPI | B2: Value
A3: Total Inspections | B3: =COUNTA(Clean_Data!A2:A1501) -> 1500
A4: Total Production | B4: =SUM(Clean_Data!J2:J1501) -> 1515186
A5: Total Defects | B5: =SUM(Clean_Data!K2:K1501) -> 26093
A6: Defect Rate | B6: =B5/B4 -> 0.017220988
A7: Quality Rate | B7: =1-B6 -> 0.98277901
A8: Total Downtime (Min) | B8: =SUM(Clean_Data!M2:M1501) -> 137341
A9: Average Cycle Time (Sec) | B9: =AVERAGE(Clean_Data!N2:N1501) -> 42.011733
A10: Average Temperature (°C) | B10: =AVERAGE(Clean_Data!O2:O1501) -> 71.636867
A11: Average Pressure (Bar) | B11: =AVERAGE(Clean_Data!P2:P1501) -> 5.2160467
A12: Average Vibration (mm/s) | B12: =AVERAGE(Clean_Data!Q2:Q1501) -> 2.7961933

Sheet Plant_Analysis
A1: Plant | B1: Inspections | C1: Production | D1: Defects | E1: Defect Rate | F1: Downtime
A2: Plant A | B2: =COUNTIF(Clean_Data!C:C,A2) -> 496 | C2: =SUMIF(Clean_Data!C:C,A2,Clean_Data!J:J) -> 504464 | D2: =SUMIF(Clean_Data!C:C,A2,Clean_Data!K:K) -> 9480 | E2: =D2/C2 -> 0.018792223 | F2: =SUMIF(Clean_Data!C:C,A2,Clean_Data!M:M) -> 47099
A3: Plant B | B3: =COUNTIF(Clean_Data!C:C,A3) -> 501 | C3: =SUMIF(Clean_Data!C:C,A3,Clean_Data!J:J) -> 506129 | D3: =SUMIF(Clean_Data!C:C,A3,Clean_Data!K:K) -> 8382 | E3: =D3/C3 -> 0.016560995 | F3: =SUMIF(Clean_Data!C:C,A3,Clean_Data!M:M) -> 43833
A4: Plant C | B4: =COUNTIF(Clean_Data!C:C,A4) -> 503 | C4: =SUMIF(Clean_Data!C:C,A4,Clean_Data!J:J) -> 504593 | D4: =SUMIF(Clean_Data!C:C,A4,Clean_Data!K:K) -> 8231 | E4: =D4/C4 -> 0.016312157 | F4: =SUMIF(Clean_Data!C:C,A4,Clean_Data!M:M) -> 46409

Sheet Line_Analysis
A1: Production Line | B1: Inspections | C1: Production | D1: Defects | E1: Defect Rate | F1: Downtime
A2: Line 1 | B2: =COUNTIF(Clean_Data!D:D,A2) -> 375 | C2: =SUMIF(Clean_Data!D:D,A2,Clean_Data!J:J) -> 379228 | D2: =SUMIF(Clean_Data!D:D,A2,Clean_Data!K:K) -> 6735 | E2: =D2/C2 -> 0.017759765 | F2: =SUMIF(Clean_Data!D:D,A2,Clean_Data!M:M) -> 33148
A3: Line 2 | B3: =COUNTIF(Clean_Data!D:D,A3) -> 354 | C3: =SUMIF(Clean_Data!D:D,A3,Clean_Data!J:J) -> 361934 | D3: =SUMIF(Clean_Data!D:D,A3,Clean_Data!K:K) -> 6203 | E3: =D3/C3 -> 0.017138484 | F3: =SUMIF(Clean_Data!D:D,A3,Clean_Data!M:M) -> 33204
A4: Line 3 | B4: =COUNTIF(Clean_Data!D:D,A4) -> 411 | C4: =SUMIF(Clean_Data!D:D,A4,Clean_Data!J:J) -> 410934 | D4: =SUMIF(Clean_Data!D:D,A4,Clean_Data!K:K) -> 7169 | E4: =D4/C4 -> 0.017445624 | F4: =SUMIF(Clean_Data!D:D,A4,Clean_Data!M:M) -> 38532
A5: Line 4 | B5: =COUNTIF(Clean_Data!D:D,A5) -> 360 | C5: =SUMIF(Clean_Data!D:D,A5,Clean_Data!J:J) -> 363090 | D5: =SUMIF(Clean_Data!D:D,A5,Clean_Data!K:K) -> 5986 | E5: =D5/C5 -> 0.016486271 | F5: =SUMIF(Clean_Data!D:D,A5,Clean_Data!M:M) -> 32457

Sheet Product_Analysis
A1: Product | B1: Inspections | C1: Production | D1: Defects | E1: Defect Rate | F1: Downtime
A2: Widget A | B2: =COUNTIF(Clean_Data!E:E,A2) -> 380 | C2: =SUMIF(Clean_Data!E:E,A2,Clean_Data!J:J) -> 388880 | D2: =SUMIF(Clean_Data!E:E,A2,Clean_Data!K:K) -> 6887 | E2: =D2/C2 -> 0.017709833 | F2: =SUMIF(Clean_Data!E:E,A2,Clean_Data!M:M) -> 35835
A3: Widget B | B3: =COUNTIF(Clean_Data!E:E,A3) -> 343 | C3: =SUMIF(Clean_Data!E:E,A3,Clean_Data!J:J) -> 339990 | D3: =SUMIF(Clean_Data!E:E,A3,Clean_Data!K:K) -> 5344 | E3: =D3/C3 -> 0.015718109 | F3: =SUMIF(Clean_Data!E:E,A3,Clean_Data!M:M) -> 31389
A4: Widget C | B4: =COUNTIF(Clean_Data!E:E,A4) -> 404 | C4: =SUMIF(Clean_Data!E:E,A4,Clean_Data!J:J) -> 415524 | D4: =SUMIF(Clean_Data!E:E,A4,Clean_Data!K:K) -> 7360 | E4: =D4/C4 -> 0.017712575 | F4: =SUMIF(Clean_Data!E:E,A4,Clean_Data!M:M) -> 37397
A5: Widget D | B5: =COUNTIF(Clean_Data!E:E,A5) -> 373 | C5: =SUMIF(Clean_Data!E:E,A5,Clean_Data!J:J) -> 370792 | D5: =SUMIF(Clean_Data!E:E,A5,Clean_Data!K:K) -> 6502 | E5: =D5/C5 -> 0.017535438 | F5: =SUMIF(Clean_Data!E:E,A5,Clean_Data!M:M) -> 32720

Sheet Shift_Analysis
A1: Shift | B1: Inspections | C1: Production | D1: Defects | E1: Defect Rate | F1: Downtime
A2: Morning | B2: =COUNTIF(Clean_Data!F:F,A2) -> 621 | C2: =SUMIF(Clean_Data!F:F,A2,Clean_Data!J:J) -> 624797 | D2: =SUMIF(Clean_Data!F:F,A2,Clean_Data!K:K) -> 11274 | E2: =D2/C2 -> 0.018044261 | F2: =SUMIF(Clean_Data!F:F,A2,Clean_Data!M:M) -> 57379
A3: Evening | B3: =COUNTIF(Clean_Data!F:F,A3) -> 551 | C3: =SUMIF(Clean_Data!F:F,A3,Clean_Data!J:J) -> 566818 | D3: =SUMIF(Clean_Data!F:F,A3,Clean_Data!K:K) -> 9588 | E3: =D3/C3 -> 0.016915483 | F3: =SUMIF(Clean_Data!F:F,A3,Clean_Data!M:M) -> 51162
A4: Night | B4: =COUNTIF(Clean_Data!F:F,A4) -> 328 | C4: =SUMIF(Clean_Data!F:F,A4,Clean_Data!J:J) -> 323571 | D4: =SUMIF(Clean_Data!F:F,A4,Clean_Data!K:K) -> 5231 | E4: =D4/C4 -> 0.016166467 | F4: =SUMIF(Clean_Data!F:F,A4,Clean_Data!M:M) -> 28800

Sheet Defect_Type_Analysis
A1: Defect Type | B1: Defect Count | C1: Defect %
A2: Assembly Error | B2: 4645 | C2: =B2/SUM($B$2:$B$8) -> 0.17801709
A3: Color Defect | B3: 4198 | C3: =B3/SUM($B$2:$B$8) -> 0.16088606
A4: Crack | B4: 4459 | C4: =B4/SUM($B$2:$B$8) -> 0.17088874
A5: Dent | B5: 4628 | C5: =B5/SUM($B$2:$B$8) -> 0.17736558
A6: Dimension Error | B6: 4063 | C6: =B6/SUM($B$2:$B$8) -> 0.15571226
A7: Scratch | B7: 3889 | C7: =B7/SUM($B$2:$B$8) -> 0.1490438
A8: Unknown | B8: 211 | C8: =B8/SUM($B$2:$B$8) -> 0.00808646

Sheet Monthly_Analysis
A1: Month | B1: Inspections | C1: Production | D1: Defects | E1: Downtime
A2: January | B2: =COUNTIFS(Clean_Data!B:B,">="&DATE(2025,MONTH(DATEVALUE(A2&" 1")),1),Clean_Data!B:B,"<"&EDATE(DATE(2025,MONTH(DATEVALUE(A2&" 1")),1),1)) -> 134 | C2: =SUMIFS(Clean_Data!J:J,Clean_Data!B:B,">="&DATE(2025,MONTH(DATEVALUE(A2&" 1")),1),Clean_Data!B:B,"<"&EDATE(DATE(2025,MONTH(DATEVALUE(A2&" 1")),1),1)) -> 138950 | D2: =SUMIFS(Clean_Data!K:K,Clean_Data!B:B,">="&DATE(2025,MONTH(DATEVALUE(A2&" 1")),1),Clean_Data!B:B,"<"&EDATE(DATE(2025,MONTH(DATEVALUE(A2&" 1")),1),1)) -> 2267 | E2: =SUMIFS(Clean_Data!M:M,Clean_Data!B:B,">="&DATE(2025,MONTH(DATEVALUE(A2&" 1")),1),Clean_Data!B:B,"<"&EDATE(DATE(2025,MONTH(DATEVALUE(A2&" 1")),1),1)) -> 12576
A3: February | B3: =COUNTIFS(Clean_Data!B:B,">="&DATE(2025,MONTH(DATEVALUE(A3&" 1")),1),Clean_Data!B:B,"<"&EDATE(DATE(2025,MONTH(DATEVALUE(A3&" 1")),1),1)) -> 119 | C3: =SUMIFS(Clean_Data!J:J,Clean_Data!B:B,">="&DATE(2025,MONTH(DATEVALUE(A3&" 1")),1),Clean_Data!B:B,"<"&EDATE(DATE(2025,MONTH(DATEVALUE(A3&" 1")),1),1)) -> 119633 | D3: =SUMIFS(Clean_Data!K:K,Clean_Data!B:B,">="&DATE(2025,MONTH(DATEVALUE(A3&" 1")),1),Clean_Data!B:B,"<"&EDATE(DATE(2025,MONTH(DATEVALUE(A3&" 1")),1),1)) -> 1994 | E3: =SUMIFS(Clean_Data!M:M,Clean_Data!B:B,">="&DATE(2025,MONTH(DATEVALUE(A3&" 1")),1),Clean_Data!B:B,"<"&EDATE(DATE(2025,MONTH(DATEVALUE(A3&" 1")),1),1)) -> 10902
A4: March | B4: =COUNTIFS(Clean_Data!B:B,">="&DATE(2025,MONTH(DATEVALUE(A4&" 1")),1),Clean_Data!B:B,"<"&EDATE(DATE(2025,MONTH(DATEVALUE(A4&" 1")),1),1)) -> 140 | C4: =SUMIFS(Clean_Data!J:J,Clean_Data!B:B,">="&DATE(2025,MONTH(DATEVALUE(A4&" 1")),1),Clean_Data!B:B,"<"&EDATE(DATE(2025,MONTH(DATEVALUE(A4&" 1")),1),1)) -> 147157 | D4: =SUMIFS(Clean_Data!K:K,Clean_Data!B:B,">="&DATE(2025,MONTH(DATEVALUE(A4&" 1")),1),Clean_Data!B:B,"<"&EDATE(DATE(2025,MONTH(DATEVALUE(A4&" 1")),1),1)) -> 2393 | E4: =SUMIFS(Clean_Data!M:M,Clean_Data!B:B,">="&DATE(2025,MONTH(DATEVALUE(A4&" 1")),1),Clean_Data!B:B,"<"&EDATE(DATE(2025,MONTH(DATEVALUE(A4&" 1")),1),1)) -> 12262
A5: April | B5: =COUNTIFS(Clean_Data!B:B,">="&DATE(2025,MONTH(DATEVALUE(A5&" 1")),1),Clean_Data!B:B,"<"&EDATE(DATE(2025,MONTH(DATEVALUE(A5&" 1")),1),1)) -> 130 | C5: =SUMIFS(Clean_Data!J:J,Clean_Data!B:B,">="&DATE(2025,MONTH(DATEVALUE(A5&" 1")),1),Clean_Data!B:B,"<"&EDATE(DATE(2025,MONTH(DATEVALUE(A5&" 1")),1),1)) -> 127915 | D5: =SUMIFS(Clean_Data!K:K,Clean_Data!B:B,">="&DATE(2025,MONTH(DATEVALUE(A5&" 1")),1),Clean_Data!B:B,"<"&EDATE(DATE(2025,MONTH(DATEVALUE(A5&" 1")),1),1)) -> 2387 | E5: =SUMIFS(Clean_Data!M:M,Clean_Data!B:B,">="&DATE(2025,MONTH(DATEVALUE(A5&" 1")),1),Clean_Data!B:B,"<"&EDATE(DATE(2025,MONTH(DATEVALUE(A5&" 1")),1),1)) -> 11651
A6: May | B6: =COUNTIFS(Clean_Data!B:B,">="&DATE(2025,MONTH(DATEVALUE(A6&" 1")),1),Clean_Data!B:B,"<"&EDATE(DATE(2025,MONTH(DATEVALUE(A6&" 1")),1),1)) -> 130 | C6: =SUMIFS(Clean_Data!J:J,Clean_Data!B:B,">="&DATE(2025,MONTH(DATEVALUE(A6&" 1")),1),Clean_Data!B:B,"<"&EDATE(DATE(2025,MONTH(DATEVALUE(A6&" 1")),1),1)) -> 131525 | D6: =SUMIFS(Clean_Data!K:K,Clean_Data!B:B,">="&DATE(2025,MONTH(DATEVALUE(A6&" 1")),1),Clean_Data!B:B,"<"&EDATE(DATE(2025,MONTH(DATEVALUE(A6&" 1")),1),1)) -> 2687 | E6: =SUMIFS(Clean_Data!M:M,Clean_Data!B:B,">="&DATE(2025,MONTH(DATEVALUE(A6&" 1")),1),Clean_Data!B:B,"<"&EDATE(DATE(2025,MONTH(DATEVALUE(A6&" 1")),1),1)) -> 12691
A7: June | B7: =COUNTIFS(Clean_Data!B:B,">="&DATE(2025,MONTH(DATEVALUE(A7&" 1")),1),Clean_Data!B:B,"<"&EDATE(DATE(2025,MONTH(DATEVALUE(A7&" 1")),1),1)) -> 113 | C7: =SUMIFS(Clean_Data!J:J,Clean_Data!B:B,">="&DATE(2025,MONTH(DATEVALUE(A7&" 1")),1),Clean_Data!B:B,"<"&EDATE(DATE(2025,MONTH(DATEVALUE(A7&" 1")),1),1)) -> 116763 | D7: =SUMIFS(Clean_Data!K:K,Clean_Data!B:B,">="&DATE(2025,MONTH(DATEVALUE(A7&" 1")),1),Clean_Data!B:B,"<"&EDATE(DATE(2025,MONTH(DATEVALUE(A7&" 1")),1),1)) -> 2151 | E7: =SUMIFS(Clean_Data!M:M,Clean_Data!B:B,">="&DATE(2025,MONTH(DATEVALUE(A7&" 1")),1),Clean_Data!B:B,"<"&EDATE(DATE(2025,MONTH(DATEVALUE(A7&" 1")),1),1)) -> 10179
A8: July | B8: =COUNTIFS(Clean_Data!B:B,">="&DATE(2025,MONTH(DATEVALUE(A8&" 1")),1),Clean_Data!B:B,"<"&EDATE(DATE(2025,MONTH(DATEVALUE(A8&" 1")),1),1)) -> 115 | C8: =SUMIFS(Clean_Data!J:J,Clean_Data!B:B,">="&DATE(2025,MONTH(DATEVALUE(A8&" 1")),1),Clean_Data!B:B,"<"&EDATE(DATE(2025,MONTH(DATEVALUE(A8&" 1")),1),1)) -> 116318 | D8: =SUMIFS(Clean_Data!K:K,Clean_Data!B:B,">="&DATE(2025,MONTH(DATEVALUE(A8&" 1")),1),Clean_Data!B:B,"<"&EDATE(DATE(2025,MONTH(DATEVALUE(A8&" 1")),1),1)) -> 2288 | E8: =SUMIFS(Clean_Data!M:M,Clean_Data!B:B,">="&DATE(2025,MONTH(DATEVALUE(A8&" 1")),1),Clean_Data!B:B,"<"&EDATE(DATE(2025,MONTH(DATEVALUE(A8&" 1")),1),1)) -> 9547
A9: August | B9: =COUNTIFS(Clean_Data!B:B,">="&DATE(2025,MONTH(DATEVALUE(A9&" 1")),1),Clean_Data!B:B,"<"&EDATE(DATE(2025,MONTH(DATEVALUE(A9&" 1")),1),1)) -> 118 | C9: =SUMIFS(Clean_Data!J:J,Clean_Data!B:B,">="&DATE(2025,MONTH(DATEVALUE(A9&" 1")),1),Clean_Data!B:B,"<"&EDATE(DATE(2025,MONTH(DATEVALUE(A9&" 1")),1),1)) -> 119974 | D9: =SUMIFS(Clean_Data!K:K,Clean_Data!B:B,">="&DATE(2025,MONTH(DATEVALUE(A9&" 1")),1),Clean_Data!B:B,"<"&EDATE(DATE(2025,MONTH(DATEVALUE(A9&" 1")),1),1)) -> 2025 | E9: =SUMIFS(Clean_Data!M:M,Clean_Data!B:B,">="&DATE(2025,MONTH(DATEVALUE(A9&" 1")),1),Clean_Data!B:B,"<"&EDATE(DATE(2025,MONTH(DATEVALUE(A9&" 1")),1),1)) -> 11030
A10: September | B10: =COUNTIFS(Clean_Data!B:B,">="&DATE(2025,MONTH(DATEVALUE(A10&" 1")),1),Clean_Data!B:B,"<"&EDATE(DATE(2025,MONTH(DATEVALUE(A10&" 1")),1),1)) -> 106 | C10: =SUMIFS(Clean_Data!J:J,Clean_Data!B:B,">="&DATE(2025,MONTH(DATEVALUE(A10&" 1")),1),Clean_Data!B:B,"<"&EDATE(DATE(2025,MONTH(DATEVALUE(A10&" 1")),1),1)) -> 101139 | D10: =SUMIFS(Clean_Data!K:K,Clean_Data!B:B,">="&DATE(2025,MONTH(DATEVALUE(A10&" 1")),1),Clean_Data!B:B,"<"&EDATE(DATE(2025,MONTH(DATEVALUE(A10&" 1")),1),1)) -> 1874 | E10: =SUMIFS(Clean_Data!M:M,Clean_Data!B:B,">="&DATE(2025,MONTH(DATEVALUE(A10&" 1")),1),Clean_Data!B:B,"<"&EDATE(DATE(2025,MONTH(DATEVALUE(A10&" 1")),1),1)) -> 9512
A11: October | B11: =COUNTIFS(Clean_Data!B:B,">="&DATE(2025,MONTH(DATEVALUE(A11&" 1")),1),Clean_Data!B:B,"<"&EDATE(DATE(2025,MONTH(DATEVALUE(A11&" 1")),1),1)) -> 141 | C11: =SUMIFS(Clean_Data!J:J,Clean_Data!B:B,">="&DATE(2025,MONTH(DATEVALUE(A11&" 1")),1),Clean_Data!B:B,"<"&EDATE(DATE(2025,MONTH(DATEVALUE(A11&" 1")),1),1)) -> 139382 | D11: =SUMIFS(Clean_Data!K:K,Clean_Data!B:B,">="&DATE(2025,MONTH(DATEVALUE(A11&" 1")),1),Clean_Data!B:B,"<"&EDATE(DATE(2025,MONTH(DATEVALUE(A11&" 1")),1),1)) -> 2212 | E11: =SUMIFS(Clean_Data!M:M,Clean_Data!B:B,">="&DATE(2025,MONTH(DATEVALUE(A11&" 1")),1),Clean_Data!B:B,"<"&EDATE(DATE(2025,MONTH(DATEVALUE(A11&" 1")),1),1)) -> 13057
A12: November | B12: =COUNTIFS(Clean_Data!B:B,">="&DATE(2025,MONTH(DATEVALUE(A12&" 1")),1),Clean_Data!B:B,"<"&EDATE(DATE(2025,MONTH(DATEVALUE(A12&" 1")),1),1)) -> 119 | C12: =SUMIFS(Clean_Data!J:J,Clean_Data!B:B,">="&DATE(2025,MONTH(DATEVALUE(A12&" 1")),1),Clean_Data!B:B,"<"&EDATE(DATE(2025,MONTH(DATEVALUE(A12&" 1")),1),1)) -> 120693 | D12: =SUMIFS(Clean_Data!K:K,Clean_Data!B:B,">="&DATE(2025,MONTH(DATEVALUE(A12&" 1")),1),Clean_Data!B:B,"<"&EDATE(DATE(2025,MONTH(DATEVALUE(A12&" 1")),1),1)) -> 1884 | E12: =SUMIFS(Clean_Data!M:M,Clean_Data!B:B,">="&DATE(2025,MONTH(DATEVALUE(A12&" 1")),1),Clean_Data!B:B,"<"&EDATE(DATE(2025,MONTH(DATEVALUE(A12&" 1")),1),1)) -> 10757
A13: December | B13: =COUNTIFS(Clean_Data!B:B,">="&DATE(2025,MONTH(DATEVALUE(A13&" 1")),1),Clean_Data!B:B,"<"&EDATE(DATE(2025,MONTH(DATEVALUE(A13&" 1")),1),1)) -> 135 | C13: =SUMIFS(Clean_Data!J:J,Clean_Data!B:B,">="&DATE(2025,MONTH(DATEVALUE(A13&" 1")),1),Clean_Data!B:B,"<"&EDATE(DATE(2025,MONTH(DATEVALUE(A13&" 1")),1),1)) -> 135737 | D13: =SUMIFS(Clean_Data!K:K,Clean_Data!B:B,">="&DATE(2025,MONTH(DATEVALUE(A13&" 1")),1),Clean_Data!B:B,"<"&EDATE(DATE(2025,MONTH(DATEVALUE(A13&" 1")),1),1)) -> 1931 | E13: =SUMIFS(Clean_Data!M:M,Clean_Data!B:B,">="&DATE(2025,MONTH(DATEVALUE(A13&" 1")),1),Clean_Data!B:B,"<"&EDATE(DATE(2025,MONTH(DATEVALUE(A13&" 1")),1),1)) -> 13177

Sheet Outlier_Analysis
A1: Metric | B1: Investigate Count | C1: Normal Count
A2: Temperature | B2: =COUNTIF(Clean_Data!U:U,"Investigate") -> 3 | C2: =COUNTIF(Clean_Data!U:U,"Normal") -> 1497
A3: Pressure | B3: =COUNTIF(Clean_Data!V:V,"Investigate") -> 2 | C3: =COUNTIF(Clean_Data!V:V,"Normal") -> 1498
A4: Vibration | B4: =COUNTIF(Clean_Data!W:W,"Investigate") -> 3 | C4: =COUNTIF(Clean_Data!W:W,"Normal") -> 1497
